Workbook

Sheet 안내
A1: 주제부 판정 시트 (CT2S-1.0 · 적용 보충 A1 기준)
A2: 작성 2026-10-05. 규칙표 요약은 '규칙표' 탭에 있고, 판정은 규칙표 전문(A_W_단순규칙확정과_실행지시_CT2S_1.0_2026-10-04.docx)을 따른다.
A4: 1. 탭의 쓰임
A5: 독립판정 | B5: 사람이 모델 예측과 AI 판정을 보지 않고 규칙표만으로 판정한다. 학습자 글에서의 모델 성능을 사람 기준으로 재는 데 쓴다(100문장).
A6: 검토(AI초안) | B6: AI가 먼저 판정한 초안을 사람이 검토해 수용하거나 고친다. AI 적용안의 질(사람이 고친 비율)을 재는 데 쓴다(200문장). 모델 성능 평가에는 쓰지 않는다.
A7: 연습문항 | B7: 판정 훈련용 예문 25개. 권장 답안은 별도 파일 '연습문항_권장답안_2026-10-05.md'에 있다. 예문은 학습자 주장 글의 흔한 구성을 본떠 새로 만든 것이며 실제 학습자 글이 아니다.
A8: 집계 | B8: 독립판정·검토 탭의 수를 자동으로 센다. 고치지 않는다.
A10: 2. 칸 색 약속
A11: 회색 칸 | B11: 판정 전에 준비하는 사람이 채운다(문장ID, 원문, 앞 문맥, AI 초안 등). 판정자는 고치지 않는다.
A12: 노란 칸 | B12: 판정자가 채운다.
A13: 초록 칸 | B13: 자동 계산. 고치지 않는다.
A14: 파란 기울임 행 | B14: 작성 예시. 실제 자료를 넣기 전에 지워도 되고 남겨도 된다(집계에 들어가지 않는다).
A16: 3. 적는 방법
A17: 한 행 | B17: 분석 단위(절) 하나. 한 문장에 단위가 여럿이면 행을 여럿 쓰고, 문장ID·원문 같은 회색 칸은 행마다 똑같이 둔다.
A18: 단위 번호 | B18: 단위가 시작하는 위치 순서로 U1, U2 … 를 붙인다. 보고절처럼 내용절을 감싸 끊긴 단위는 단위 원문에 '…'를 넣는다(예: 저는 … 생각합니다).
A19: 절이 없는 문장 | B19: 문장 전체가 절로 세지 않는 단편·나열이면(C5) 한 행만 쓰고 단위 '-', 적용 규칙 'C5', 주제부 값 '절 아님'.
A20: 주제부 원문 | B20: 대상 문장에서 그대로 복사한다. 맞춤법·띄어쓰기를 고치지 않는다. 붙여 쓴 어절 안에서 끝나면 어절 중간에서 끊는다(예: '나는e스포츠가'에서 '나는').
A21: 주제부 값 | B21: 범위: T2·T3·T4로 주제부가 있을 때. / 연결·논평만: T1·T5인데 절 첫머리에 연결·논평 표현이 있을 때(그 표현만 주제부 원문에 적는다). / 명시 없음: T1·T5이고 연결·논평 표현도 없을 때. / 유보: 구조가 불명확해 단위나 주어를 정할 수 없을 때. / 절 아님: C5.
A22: 유보 | B22: 정하기 어렵다는 이유로 '명시 없음'을 고르지 않는다. 유보와 명시 없음은 다른 값이다.
A23: 근거 | B23: 규칙 번호와 결정적 단서를 한 줄로(예: 'T5: 앞 문장의 정부가 이어지는 행위자, A1②').
A24: 확신도 | B24: 상·중·하. '하'는 나중에 판단이 갈리는 유형을 모으는 데 쓴다.
A26: 4. 독립판정의 맹검 조건
A27: 보지 않는 것 | B27: 판정 대상 문장에 대한 모델 예측, A·W의 판정, AI 초안. 판정이 끝나기 전에는 검토(AI초안) 탭 작업도 하지 않는다.
A28: 판정 중 의문 | B28: 규칙표 해석이 막히면 메모 칸에 적고, 그 자리에서 규칙을 바꾸지 않은 채 끝까지 판정한다.
A29: 판정이 끝나면 | B29: 파일을 저장하고 SHA-256 지문과 날짜를 기록한다. 그 뒤에 모델 예측을 꺼내 채점한다. 지문을 고정한 뒤에는 판정을 고치지 않는다.
A31: 5. 권장 순서
A32: ① | B32: 규칙표를 읽고 연습문항을 직접 판정한 뒤 권장 답안과 견준다(판정 훈련). 논문에는 '판정자는 규칙표와 연습 예문으로 훈련했다'고 적는다.
A33: ② | B33: 독립판정 100문장 → 지문 고정.
A34: ③ | B34: 검토(AI초안) 200문장.
A35: ④ | B35: 채점(독립판정 대 모델 예측. 원하면 A의 맹검 판정 대 독립판정도).
A36: ⑤ | B36: A의 확인 표본 1 판정 파일과 권장 답안을 보며 사람 판정과 다른 곳을 정리한다.
A38: 6. 표본을 열기 전에 기록할 것
A39: 문장 추출 | B39: 어느 글에서(확인 표본 2·3 등) 몇 문장을 어떤 방법·난수 씨앗으로 뽑는지. 모델 예측을 보지 않고 뽑는다.
A40: 판정자 | B40: 누가 판정하는지, 훈련 내용(①), 두 번째 판정자가 일부를 판정하는지.
A41: 지표 | B41: 범위 정확 일치 F1, 정밀도·재현율, '없음' 판정 정확도, 유보 수. 기존 채점과 같은 정의.
A42: 보고 원칙 | B42: 결과가 기준에 못 미쳐도 보고한다. 기준값을 둔다면 열기 전에 적는다.

Sheet 규칙표
A1: 규칙표 CT2S-1.0 요약 · 적용 보충 A1 요약
A2: 요약본이다. 판정이 갈리면 규칙표 전문과 A1 문서를 따른다.
A4: 절 규칙 — 무엇을 분석 절 하나로 세는가
A5: 번호 | B5: 규칙 | C5: 예
A6: C1 | B6: 비내포 술어군 하나를 절 하나로 센다. 본용언의 보조·양태 표현은 묶는다. | C6: 줄여야 한다, 할 수 있다, 생각하지 않는다 → 술어군 하나
A7: C2 | B7: 연결절과 투사 내용절·보고절은 각각 센다. 원인·목적·시간 연결도 포함한다. | C7: -고, -지만, -면, -려면, -기 위해, -아서 / 저는 [ … 다고] 생각합니다 → 둘
A8: C3 | B8: 명사구 안의 관형절·명사절은 주분석 절 수에 더하지 않는다. | C8: [SNS를 오래 사용하는] 학생들은 → 절 수에 넣지 않음(범위 안에는 들어감)
A9: C4 | B9: 명사성 틀은 바깥 절 하나를 센다. | C9: -기 때문이다, -는 것이다, -ㄹ 예정이다
A10: C5 | B10: 서술 관계를 복원할 근거가 없는 단편·명사 나열과 관용적 담화 표현은 절로 세지 않는다. | C10: 예를 들면 A, B, C 등. / 다시 말해, 말하자면
A11: C6 | B11: 의문·명령·청유·감탄도 같은 기준으로 센다.
A13: 주제부 규칙 — 위에서부터 차례로 적용하고, 처음 맞는 규칙에서 멈춘다
A14: 번호 | B14: 조건 | C14: 주제부 | D14: 주제부 값
A15: T1 | B15: 명사성 틀이고 틀 밖의 주어가 없다. | C15: 없음. 문두 연결·논평 표현이 있으면 그것만 기록. | D15: 명시 없음 / 연결·논평만
A16: T2 | B16: 같은 분석 절에 명시 주어가 있다. | C16: 절의 시작부터 주어 성분 전체의 끝까지. | D16: 범위
A17: T3 | B17: 주어가 없고, 첫 경험 성분에 은/는이 붙거나 그 성분이 정보를 묻는 의문 성분이다. | C17: 절의 시작부터 그 성분까지. | D17: 범위
A18: T4 | B18: 주어가 없고 일반 절차·당위·조언·불특정 전언이다. 독립 명령·청유 포함. | C18: 절의 시작부터 첫 경험 성분까지. 술어군만 있으면 술어군까지. | D18: 범위
A19: T5 | B19: 그 밖의 주어 없는 절. | C19: 없음. 연결·논평 표현이 있으면 그것만 기록. | D19: 명시 없음 / 연결·논평만
A21: 적용 보충 A1 — 요지
A22: 번호 | B22: 내용
A23: T4/T5 ① | B23: 독립 명령·청유·불특정 전언은 T4.
A24: T4/T5 ② | B24: 같은 문장이나 앞 2문장에서 특정 행위자가 이어지면(이 절의 생략된 주어가 그 행위자이면) 당위 표지가 있어도 T5.
A25: T4/T5 ③ | B25: 그런 근거가 없고 일반 절차·당위·조언으로 읽히면 T4.
A26: T4/T5 ④ | B26: 그 밖은 T5.
A27: 주어 여럿 | B27: 주어 후보가 여럿이면 서술어에 가까운 직접 주어까지를 범위로 한다. | C27: SNS는 장점이 많다 → 'SNS는 장점이'
A28: 공유 주어 | B28: 여러 절이 주어를 공유하면 주어는 첫 절에만 있다. 뒤 절은 주어 없는 절로 판정. | C28: 나는 숙제를 하고 잤다 → 둘째 절은 주어 없음
A29: 보고·내용절 | B29: 보고절과 내용절을 나눠 따로 판정.
A30: 사건명사+되다 | B30: '도입이 되다'류에서는 명사가 주어. | C30: 실명제 도입이 되면 → 주어 '실명제 도입이'
A32: 성분 구분 — '절의 시작'과 '첫 경험 성분'을 가를 때
A33: 구분 | B33: 무엇 | C33: 예 | D33: 주제부와의 관계
A34: 연결 | B34: 앞뒤 문장·절을 잇는 표현 | C34: 그리고, 그래서, 그러나, 왜냐하면, 그러므로, 따라서, 첫째, 다시 말해 | D34: 절의 시작에 있으면 범위에 들어간다. 경험 성분이 아니다.
A35: 논평·호격 | B35: 필자의 태도나 청자 부르기 | C35: 솔직히, 물론, 과연, 제 생각에는, 여러분 | D35: 위와 같다. '제 생각에는'처럼 는이 붙어도 T3의 은/는 성분이 아니다.
A36: 경험 성분 | B36: 참여자(주어·목적어·보어)와 상황(시간·장소·방법 부사어) | C36: SNS를, 인터넷에서는, 지금은, 이제부터, 친구의 말을 | D36: T3·T4의 '첫 경험 성분' 후보.

Sheet 독립판정
A1: 독립 판정 — 모델 예측·AI 판정을 보지 않고 규칙표만으로
A2: 한 행 = 분석 단위 하나. 회색 칸은 준비하는 사람이, 노란 칸은 판정자가 채운다. 4–5행은 예시(집계 제외). 실제 자료는 6행부터.
A3: 판정 방식 | B3: 문장ID | C3: 글ID | D3: 학년 | E3: 과제 | F3: 앞 문맥(앞 2문장) | G3: 대상 문장 | H3: 단위 | I3: 단위 원문 | J3: 단위 종류(선택) | K3: 명시 주어(있으면) | L3: 적용 규칙 | M3: 주제부 값 | N3: 주제부 원문 | O3: 근거 | P3: 확신도 | Q3: 메모
A4: 독립 판정 | B4: 예시-1 | C4: 예시 | D4: 중1 | E4: 05 | F4: 요즘 SNS에서 악성 댓글이 많다. 피해를 입는 사람도 늘고 있다. | G4: 그래서 저는 실명제가 꼭 필요하다고 생각합니다. | H4: U1 | I4: 그래서 저는 … 생각합니다 | J4: 보고절 | K4: 저는 | L4: T2 | M4: 범위 | N4: 그래서 저는 | O4: T2: 명시 주어 '저는'. 절의 시작 '그래서'부터. | P4: 상
A5: 독립 판정 | B5: 예시-1 | C5: 예시 | D5: 중1 | E5: 05 | F5: 요즘 SNS에서 악성 댓글이 많다. 피해를 입는 사람도 늘고 있다. | G5: 그래서 저는 실명제가 꼭 필요하다고 생각합니다. | H5: U2 | I5: 실명제가 꼭 필요하다고 | J5: 내용절 | K5: 실명제가 | L5: T2 | M5: 범위 | N5: 실명제가 | O5: T2: 내용절의 주어 '실명제가'. 보고절과 나눔(A1). | P5: 상
A6: 독립 판정
A7: 독립 판정
A8: 독립 판정
A9: 독립 판정
A10: 독립 판정
A11: 독립 판정
A12: 독립 판정
A13: 독립 판정
A14: 독립 판정
A15: 독립 판정
A16: 독립 판정
A17: 독립 판정
... A400: 독립 판정

Sheet 검토(AI초안)
A1: AI 초안 검토 — AI가 먼저 판정한 것을 사람이 수용하거나 고친다
A2: 검토 칸에 수용/수정을 고른다. 수정이면 고칠 칸만 채우면 되고, 비워 둔 칸은 AI 값을 그대로 쓴다. 확정 칸(초록)은 자동. 4–5행은 예시, 실제 자료는 6행부터.
A3: 판정 방식 | B3: 문장ID | C3: 글ID | D3: 학년 | E3: 과제 | F3: 앞 문맥(앞 2문장) | G3: 대상 문장 | H3: 단위 | I3: 단위 원문 | J3: AI 규칙 | K3: AI 주제부 값 | L3: AI 주제부 원문 | M3: AI 근거 | N3: 검토 | O3: 수정 규칙 | P3: 수정 주제부 값 | Q3: 수정 주제부 원문 | R3: 수정 유형 | S3: 수정 이유 | T3: 확정 규칙 | U3: 확정 주제부 값 | V3: 확정 주제부 원문
A4: AI 초안 검토 | B4: 예시-1 | C4: 예시 | D4: 중1 | E4: 05 | F4: 요즘 SNS에서 악성 댓글이 많다. 피해를 입는 사람도 늘고 있다. | G4: 그래서 저는 실명제가 꼭 필요하다고 생각합니다. | H4: U1 | I4: 그래서 저는 … 생각합니다 | J4: T2 | K4: 범위 | L4: 저는 | M4: T2: 명시 주어 '저는' | N4: 수정 | Q4: 그래서 저는 | R4: 범위 시작 | S4: T2 범위는 절의 시작부터. 연결 표현 '그래서' 포함. | T4: =IF(N4="","",IF(AND(N4="수정",O4<>""),O4,J4)) -> T2 | U4: =IF(N4="","",IF(AND(N4="수정",P4<>""),P4,K4)) -> 범위 | V4: =IF(N4="","",IF(N4="수정",IF(Q4<>"",Q4,IF(OR(U4="명시 없음",U4="유보",U4="절 아님"),"",L4)),L4)) -> 그래서 저는
A5: AI 초안 검토 | B5: 예시-1 | C5: 예시 | D5: 중1 | E5: 05 | F5: 요즘 SNS에서 악성 댓글이 많다. 피해를 입는 사람도 늘고 있다. | G5: 그래서 저는 실명제가 꼭 필요하다고 생각합니다. | H5: U2 | I5: 실명제가 꼭 필요하다고 | J5: T2 | K5: 범위 | L5: 실명제가 | M5: T2: 내용절 주어 | N5: 수용 | T5: =IF(N5="","",IF(AND(N5="수정",O5<>""),O5,J5)) -> T2 | U5: =IF(N5="","",IF(AND(N5="수정",P5<>""),P5,K5)) -> 범위 | V5: =IF(N5="","",IF(N5="수정",IF(Q5<>"",Q5,IF(OR(U5="명시 없음",U5="유보",U5="절 아님"),"",L5)),L5)) -> 실명제가
A6: AI 초안 검토 | T6: =IF(N6="","",IF(AND(N6="수정",O6<>""),O6,J6)) | U6: =IF(N6="","",IF(AND(N6="수정",P6<>""),P6,K6)) | V6: =IF(N6="","",IF(N6="수정",IF(Q6<>"",Q6,IF(OR(U6="명시 없음",U6="유보",U6="절 아님"),"",L6)),L6))
A7: AI 초안 검토 | T7: =IF(N7="","",IF(AND(N7="수정",O7<>""),O7,J7)) | U7: =IF(N7="","",IF(AND(N7="수정",P7<>""),P7,K7)) | V7: =IF(N7="","",IF(N7="수정",IF(Q7<>"",Q7,IF(OR(U7="명시 없음",U7="유보",U7="절 아님"),"",L7)),L7))
A8: AI 초안 검토 | T8: =IF(N8="","",IF(AND(N8="수정",O8<>""),O8,J8)) | U8: =IF(N8="","",IF(AND(N8="수정",P8<>""),P8,K8)) | V8: =IF(N8="","",IF(N8="수정",IF(Q8<>"",Q8,IF(OR(U8="명시 없음",U8="유보",U8="절 아님"),"",L8)),L8))
A9: AI 초안 검토 | T9: =IF(N9="","",IF(AND(N9="수정",O9<>""),O9,J9)) | U9: =IF(N9="","",IF(AND(N9="수정",P9<>""),P9,K9)) | V9: =IF(N9="","",IF(N9="수정",IF(Q9<>"",Q9,IF(OR(U9="명시 없음",U9="유보",U9="절 아님"),"",L9)),L9))
A10: AI 초안 검토 | T10: =IF(N10="","",IF(AND(N10="수정",O10<>""),O10,J10)) | U10: =IF(N10="","",IF(AND(N10="수정",P10<>""),P10,K10)) | V10: =IF(N10="","",IF(N10="수정",IF(Q10<>"",Q10,IF(OR(U10="명시 없음",U10="유보",U10="절 아님"),"",L10)),L10))
A11: AI 초안 검토 | T11: =IF(N11="","",IF(AND(N11="수정",O11<>""),O11,J11)) | U11: =IF(N11="","",IF(AND(N11="수정",P11<>""),P11,K11)) | V11: =IF(N11="","",IF(N11="수정",IF(Q11<>"",Q11,IF(OR(U11="명시 없음",U11="유보",U11="절 아님"),"",L11)),L11))
A12: AI 초안 검토 | T12: =IF(N12="","",IF(AND(N12="수정",O12<>""),O12,J12)) | U12: =IF(N12="","",IF(AND(N12="수정",P12<>""),P12,K12)) | V12: =IF(N12="","",IF(N12="수정",IF(Q12<>"",Q12,IF(OR(U12="명시 없음",U12="유보",U12="절 아님"),"",L12)),L12))
A13: AI 초안 검토 | T13: =IF(N13="","",IF(AND(N13="수정",O13<>""),O13,J13)) | U13: =IF(N13="","",IF(AND(N13="수정",P13<>""),P13,K13)) | V13: =IF(N13="","",IF(N13="수정",IF(Q13<>"",Q13,IF(OR(U13="명시 없음",U13="유보",U13="절 아님"),"",L13)),L13))
A14: AI 초안 검토 | T14: =IF(N14="","",IF(AND(N14="수정",O14<>""),O14,J14)) | U14: =IF(N14="","",IF(AND(N14="수정",P14<>""),P14,K14)) | V14: =IF(N14="","",IF(N14="수정",IF(Q14<>"",Q14,IF(OR(U14="명시 없음",U14="유보",U14="절 아님"),"",L14)),L14))
A15: AI 초안 검토 | T15: =IF(N15="","",IF(AND(N15="수정",O15<>""),O15,J15)) | U15: =IF(N15="","",IF(AND(N15="수정",P15<>""),P15,K15)) | V15: =IF(N15="","",IF(N15="수정",IF(Q15<>"",Q15,IF(OR(U15="명시 없음",U15="유보",U15="절 아님"),"",L15)),L15))
A16: AI 초안 검토 | T16: =IF(N16="","",IF(AND(N16="수정",O16<>""),O16,J16)) | U16: =IF(N16="","",IF(AND(N16="수정",P16<>""),P16,K16)) | V16: =IF(N16="","",IF(N16="수정",IF(Q16<>"",Q16,IF(OR(U16="명시 없음",U16="유보",U16="절 아님"),"",L16)),L16))
A17: AI 초안 검토 | T17: =IF(N17="","",IF(AND(N17="수정",O17<>""),O17,J17)) | U17: =IF(N17="","",IF(AND(N17="수정",P17<>""),P17,K17)) | V17: =IF(N17="","",IF(N17="수정",IF(Q17<>"",Q17,IF(OR(U17="명시 없음",U17="유보",U17="절 아님"),"",L17)),L17))
... A700: AI 초안 검토 | T700: =IF(N700="","",IF(AND(N700="수정",O700<>""),O700,J700)) | U700: =IF(N700="","",IF(AND(N700="수정",P700<>""),P700,K700)) | V700: =IF(N700="","",IF(N700="수정",IF(Q700<>"",Q700,IF(OR(U700="명시 없음",U700="유보",U700="절 아님"),"",L700)),L700))

Sheet 연습문항
A1: 연습문항 — 직접 판정한 뒤 '연습문항_권장답안_2026-10-05.md'와 견준다
A2: 문항마다 3행을 두었다. 단위가 하나면 나머지 행은 비워 두고, 셋보다 많으면 행을 삽입한다. 예문은 새로 만든 것이며 실제 학습자 글이 아니다.
A3: 판정 방식 | B3: 문장ID | C3: 글ID | D3: 학년 | E3: 과제 | F3: 앞 문맥(앞 2문장) | G3: 대상 문장 | H3: 단위 | I3: 단위 원문 | J3: 단위 종류(선택) | K3: 명시 주어(있으면) | L3: 적용 규칙 | M3: 주제부 값 | N3: 주제부 원문 | O3: 근거 | P3: 확신도 | Q3: 메모
A4: 연습 | B4: P01 | C4: - | D4: - | E4: - | G4: 그러나 제 생각에는 SNS 실명제가 꼭 필요합니다.
A5: 연습 | B5: P01 | C5: - | D5: - | E5: - | G5: 그러나 제 생각에는 SNS 실명제가 꼭 필요합니다.
A6: 연습 | B6: P01 | C6: - | D6: - | E6: - | G6: 그러나 제 생각에는 SNS 실명제가 꼭 필요합니다.
A7: 연습 | B7: P02 | C7: - | D7: - | E7: - | G7: 저는 e스포츠도 스포츠라고 생각합니다.
A8: 연습 | B8: P02 | C8: - | D8: - | E8: - | G8: 저는 e스포츠도 스포츠라고 생각합니다.
A9: 연습 | B9: P02 | C9: - | D9: - | E9: - | G9: 저는 e스포츠도 스포츠라고 생각합니다.
A10: 연습 | B10: P03 | C10: - | D10: - | E10: - | G10: 나는e스포츠가 건강에 해롭다고 생각하지 않는다.
A11: 연습 | B11: P03 | C11: - | D11: - | E11: - | G11: 나는e스포츠가 건강에 해롭다고 생각하지 않는다.
A12: 연습 | B12: P03 | C12: - | D12: - | E12: - | G12: 나는e스포츠가 건강에 해롭다고 생각하지 않는다.
A13: 연습 | B13: P04 | C13: - | D13: - | E13: - | G13: SNS는 장점도 많지만 단점도 많다.
A14: 연습 | B14: P04 | C14: - | D14: - | E14: - | G14: SNS는 장점도 많지만 단점도 많다.
A15: 연습 | B15: P04 | C15: - | D15: - | E15: - | G15: SNS는 장점도 많지만 단점도 많다.
... A18: 연습 | B18: P05 | C18: - | D18: - | E18: - | G18: SNS를 오래 사용하는 학생들은 수면 시간이 부족해진다.
A19: 연습 | B19: P06 | C19: - | D19: - | E19: - | F19: 악성 댓글을 다는 사람은 처벌을 받아야 한다. | G19: 왜냐하면 악성 댓글은 사람의 마음에 큰 상처를 남기기 때문이다.
A20: 연습 | B20: P06 | C20: - | D20: - | E20: - | F20: 악성 댓글을 다는 사람은 처벌을 받아야 한다. | G20: 왜냐하면 악성 댓글은 사람의 마음에 큰 상처를 남기기 때문이다.
A21: 연습 | B21: P06 | C21: - | D21: - | E21: - | F21: 악성 댓글을 다는 사람은 처벌을 받아야 한다. | G21: 왜냐하면 악성 댓글은 사람의 마음에 큰 상처를 남기기 때문이다.
A22: 연습 | B22: P07 | C22: - | D22: - | E22: - | F22: 악성 댓글을 다는 사람은 처벌을 받아야 한다. | G22: 그 이유는 악성 댓글이 사람의 마음에 큰 상처를 남기기 때문이다.
A23: 연습 | B23: P07 | C23: - | D23: - | E23: - | F23: 악성 댓글을 다는 사람은 처벌을 받아야 한다. | G23: 그 이유는 악성 댓글이 사람의 마음에 큰 상처를 남기기 때문이다.
A24: 연습 | B24: P07 | C24: - | D24: - | E24: - | F24: 악성 댓글을 다는 사람은 처벌을 받아야 한다. | G24: 그 이유는 악성 댓글이 사람의 마음에 큰 상처를 남기기 때문이다.
A25: 연습 | B25: P08 | C25: - | D25: - | E25: - | G25: 인터넷에서는 거짓 정보도 쉽게 볼 수 있다.
A26: 연습 | B26: P08 | C26: - | D26: - | E26: - | G26: 인터넷에서는 거짓 정보도 쉽게 볼 수 있다.
A27: 연습 | B27: P08 | C27: - | D27: - | E27: - | G27: 인터넷에서는 거짓 정보도 쉽게 볼 수 있다.
A28: 연습 | B28: P09 | C28: - | D28: - | E28: - | G28: 이런 악습은 하루빨리 없애야 한다.
A29: 연습 | B29: P09 | C29: - | D29: - | E29: - | G29: 이런 악습은 하루빨리 없애야 한다.
A30: 연습 | B30: P09 | C30: - | D30: - | E30: - | G30: 이런 악습은 하루빨리 없애야 한다.
A31: 연습 | B31: P10 | C31: - | D31: - | E31: - | F31: 학교 폭력은 점점 늘고 있다. | G31: 그렇다면 어떻게 해야 할까?
A32: 연습 | B32: P10 | C32: - | D32: - | E32: - | F32: 학교 폭력은 점점 늘고 있다. | G32: 그렇다면 어떻게 해야 할까?
A33: 연습 | B33: P10 | C33: - | D33: - | E33: - | F33: 학교 폭력은 점점 늘고 있다. | G33: 그렇다면 어떻게 해야 할까?
A34: 연습 | B34: P11 | C34: - | D34: - | E34: - | G34: 나는 처음에 e스포츠를 싫어했지만 지금은 즐겨 본다.
A35: 연습 | B35: P11 | C35: - | D35: - | E35: - | G35: 나는 처음에 e스포츠를 싫어했지만 지금은 즐겨 본다.
A36: 연습 | B36: P11 | C36: - | D36: - | E36: - | G36: 나는 처음에 e스포츠를 싫어했지만 지금은 즐겨 본다.
A37: 연습 | B37: P12 | C37: - | D37: - | E37: - | F37: 학교 폭력은 작은 다툼에서 시작되는 경우가 많다. | G37: 폭력을 예방하려면 친구의 말을 끝까지 들어 주어야 한다.
A38: 연습 | B38: P12 | C38: - | D38: - | E38: - | F38: 학교 폭력은 작은 다툼에서 시작되는 경우가 많다. | G38: 폭력을 예방하려면 친구의 말을 끝까지 들어 주어야 한다.
A39: 연습 | B39: P12 | C39: - | D39: - | E39: - | F39: 학교 폭력은 작은 다툼에서 시작되는 경우가 많다. | G39: 폭력을 예방하려면 친구의 말을 끝까지 들어 주어야 한다.
A40: 연습 | B40: P13 | C40: - | D40: - | E40: - | G40: 여러분, 악성 댓글을 달지 맙시다.
A41: 연습 | B41: P13 | C41: - | D41: - | E41: - | G41: 여러분, 악성 댓글을 달지 맙시다.
A42: 연습 | B42: P13 | C42: - | D42: - | E42: - | G42: 여러분, 악성 댓글을 달지 맙시다.
...

Sheet 집계
A1: 집계 (자동 계산 — 고치지 않는다)
A2: 예시 행(4–5행)은 세지 않는다. 문장 수는 문장ID의 종류 수다.
A4: 독립판정
A5: 문장 수 | B5: =SUMPRODUCT((독립판정!$B$6:$B$400<>"")/COUNTIF(독립판정!$B$6:$B$400,독립판정!$B$6:$B$400&"")) -> 0
A6: 분석 단위 수(단위 칸이 '-'가 아닌 행) | B6: =COUNTIF(독립판정!$H$6:$H$400,"U*") -> 0
A7: 적용 규칙 T1 | B7: =COUNTIF(독립판정!$L$6:$L$400,"T1") -> 0
A8: 적용 규칙 T2 | B8: =COUNTIF(독립판정!$L$6:$L$400,"T2") -> 0
A9: 적용 규칙 T3 | B9: =COUNTIF(독립판정!$L$6:$L$400,"T3") -> 0
A10: 적용 규칙 T4 | B10: =COUNTIF(독립판정!$L$6:$L$400,"T4") -> 0
A11: 적용 규칙 T5 | B11: =COUNTIF(독립판정!$L$6:$L$400,"T5") -> 0
A12: 적용 규칙 유보 | B12: =COUNTIF(독립판정!$L$6:$L$400,"유보") -> 0
A13: 적용 규칙 C5 | B13: =COUNTIF(독립판정!$L$6:$L$400,"C5") -> 0
A14: 주제부 값 범위 | B14: =COUNTIF(독립판정!$M$6:$M$400,"범위") -> 0
A15: 주제부 값 연결·논평만 | B15: =COUNTIF(독립판정!$M$6:$M$400,"연결·논평만") -> 0
A16: 주제부 값 명시 없음 | B16: =COUNTIF(독립판정!$M$6:$M$400,"명시 없음") -> 0
A17: 주제부 값 유보 | B17: =COUNTIF(독립판정!$M$6:$M$400,"유보") -> 0
A18: 주제부 값 절 아님 | B18: =COUNTIF(독립판정!$M$6:$M$400,"절 아님") -> 0
A19: 확신도 '하'인 단위 | B19: =COUNTIF(독립판정!$P$6:$P$400,"하") -> 0 | D19: 판단이 갈리는 유형을 모을 때 필터로 본다.
A20: 적용 규칙이 빈 행(판정 누락) | B20: =SUMPRODUCT((독립판정!$B$6:$B$400<>"")*(독립판정!$L$6:$L$400="")) -> 0 | D20: 0이어야 판정 완료.
A22: 검토(AI초안)
A23: 문장 수 | B23: =SUMPRODUCT(('검토(AI초안)'!$B$6:$B$700<>"")/COUNTIF('검토(AI초안)'!$B$6:$B$700,'검토(AI초안)'!$B$6:$B$700&"")) -> 0
A24: 검토한 단위 수 | B24: =COUNTIF('검토(AI초안)'!$N$6:$N$700,"수용")+COUNTIF('검토(AI초안)'!$N$6:$N$700,"수정") -> 0
A25: 수정한 단위 수 | B25: =COUNTIF('검토(AI초안)'!$N$6:$N$700,"수정") -> 0
A26: 단위 수정 비율 | B26: =IF(B24=0,"",B25/B24) | D26: 사람이 AI 초안을 고친 비율(단위 기준).
A27: 하나라도 수정한 문장 수 | B27: =SUMPRODUCT(('검토(AI초안)'!$B$6:$B$700<>"")*(COUNTIFS('검토(AI초안)'!$B$6:$B$700,'검토(AI초안)'!$B$6:$B$700,'검토(AI초안)'!$N$6:$N$700,"수정")>0)/COUNTIF('검토(AI초안)'!$B$6:$B$700,'검토(AI초안)'!$B$6:$B$700&"")) -> 0
A28: 문장 수정 비율 | B28: =IF(B23=0,"",B27/B23) | D28: AI 초안이 문장째 그대로 받아들여지지 않은 비율.
A29: 규칙 번호가 바뀐 단위 수 | B29: =SUMPRODUCT(('검토(AI초안)'!$N$6:$N$700="수정")*('검토(AI초안)'!$T$6:$T$700<>'검토(AI초안)'!$J$6:$J$700)) -> 0
A30: 검토 칸이 빈 행(검토 누락) | B30: =SUMPRODUCT(('검토(AI초안)'!$B$6:$B$700<>"")*('검토(AI초안)'!$N$6:$N$700="")) -> 0 | D30: 0이어야 검토 완료.
A31: 수정 유형별 단위 수
A32: 단위 나누기 | B32: =COUNTIF('검토(AI초안)'!$R$6:$R$700,"단위 나누기") -> 0
A33: 주어 식별 | B33: =COUNTIF('검토(AI초안)'!$R$6:$R$700,"주어 식별") -> 0
A34: 범위 시작 | B34: =COUNTIF('검토(AI초안)'!$R$6:$R$700,"범위 시작") -> 0
A35: 범위 끝 | B35: =COUNTIF('검토(AI초안)'!$R$6:$R$700,"범위 끝") -> 0
A36: T3 은/는 성분 | B36: =COUNTIF('검토(AI초안)'!$R$6:$R$700,"T3 은/는 성분") -> 0
A37: T4·T5 구분 | B37: =COUNTIF('검토(AI초안)'!$R$6:$R$700,"T4·T5 구분") -> 0
A38: 명사성 틀 | B38: =COUNTIF('검토(AI초안)'!$R$6:$R$700,"명사성 틀") -> 0
A39: 연결·논평 기록 | B39: =COUNTIF('검토(AI초안)'!$R$6:$R$700,"연결·논평 기록") -> 0
A40: 유보 여부 | B40: =COUNTIF('검토(AI초안)'!$R$6:$R$700,"유보 여부") -> 0
A41: 기타 | B41: =COUNTIF('검토(AI초안)'!$R$6:$R$700,"기타") -> 0
